Workbook
Name Slicer_Is_Weekend_or_BH: #N/A
Name Slicer_Month_Filter: #N/A
Name Slicer_Year_Filter: #N/A

Sheet Readme
B2: 🥩 Weather-Driven FMCG Supply Chain & Margin Analytics
B4: 📌 Project Overview
B5: This commercial-grade data analytics project explores the correlation between weather conditions (daily temperature fluctuations/extreme rain) and FMCG operations in Gloucestershire, UK. The project transitions raw operational data into actionable business insights to optimize inventory levels, eliminate waste, and protect financial margins during weather anomalies.
B9: 📊 Key Business Insights & Analytical Framework (From the Report):
B11: 1. Data Quality Assessment (DQA): Audited and cleaned a historical dataset of 300 daily records (2023–2026) using Power Query, standardizing calendar tags, handling empty financial rows, and creating conditional attributes for Extreme Heat ($>30^\circ\text{C}$).
B12: 2. The "Ruined Weekend Effect" (Bank Holiday Analysis): Quantified baseline financial losses from supply chain pre-allocation during extreme weather.
B13: Extreme Heat Bank Holiday: Generates an average loss of £1,258.00/day in wasted meat stock.
B14: Heavy Rain Bank Holiday: Generates an average loss of £1,124.80/day.
B15: Standard Sunny Weekends incur £0.00 in weather-related spoilage.
B16: 3. Market Basket Shift (Mirror Effect): Demonstrated that consumer demand during heatwaves shifts from meat to refreshments:
B17: Meat Demand (Beef & Pork): -85%
B18: Bagged Ice Demand: +450% | Ice Cream: +310% | Soft Drinks: +240%
... B34: Focus: Data Analytics | Supply Chain Logistics | FMCG Operations

Sheet Change_Log
A1: Stage | B1: Version | C1: Date | D1: Module / Functionality | E1: Description of Changes | F1: Status
A2: Stage 1: Ingestion | B2: v0.1 | C2: 46204 | D2: Web Data Ingestion | E2: Set up automatic data import from external websites (temperature table import, pork and beef procurement and sales volumes import ). | F2: Completed
A3: Stage 2: Cleaning | B3: v0.2 | C3: 46206 | D3: Data Cleaning & Parsing | E3: Developed a "raw" data cleaning algorithm: text splitting via TEXTSPLIT, duplicate removal, and handling empty values using pad_with = "". | F3: Completed
A4: Stage 3: Modeling | B4: v1.0 | C4: 46208 | D4: Temperature Matrix | E4: Formed the main temperature calculation table. Integrated XLOOKUP functions for reverse lookup of the latest values and date handling. | F4: Completed
A5: Stage 3: Modeling | B5: v1.1 | C5: 46209 | D5: Data Aggregation | E5: Set up analytical formulas (SUMIFS, COUNTIFS) and dynamic sorting via SORTBY for data grouping. | F5: Completed
A6: Stage 4: Presentation | B6: v1.2 | C6: Current | D6: Dashboard & UI | E6: Creating the final dashboard with charts, configuring the cell color code, and drafting instructions on the Readme sheet. | F6: Completed

Sheet Resource links
B1: Resource links
A2: 1 | B2: Beef Market Trends & Dynamics | C2: Inputs / Market_Analysis | D2: Monthly | E2: AHDB Beef Markets
A3: 2 | B3: Meat Consumption & Industry Facts | C3: Readme / Assumptions | D3: Annually | E3: Food Foundation Meat Facts
A4: 3 | B4: Regional Weather Data (Gloucester) | C4: Temperature_Matrix | D4: Daily / Weekly | E4: Meteostat Gloucester Weather
A5: 4 | B5: GB Deadweight Cattle Prices | C5: Calculations / Pricing | D5: Weekly | E5: AHDB Deadweight Cattle Prices

Sheet Project clean data
A1: Date | B1: Is_Weekend_or_BH | C1: Max_Temperature_C | D1: Rainfall_mm | E1: Beef_Historical_Order_kg | F1: Beef_Actual_Sales_kg | G1: Beef_Wasted_Stock_kg | H1: Beef_Financial_Loss_£ | I1: Pork_Historical_Order_kg | J1: Pork_Actual_Sales_kg | K1: Pork_Wasted_Stock_kg | L1: Pork_Financial_Loss_£ | M1: Weather_Condition | N1: Year_Filter | O1: Month_Filter
A2: 45047 | B2: YES | C2: =_xlfn.XLOOKUP(A2,Weather_clean_data!A:A,Weather_clean_data!B:B,0) -> 18 | D2: =_xlfn.XLOOKUP(A2, Weather_clean_data!A:A, Weather_clean_data!C:C, 0) -> 1.3 | E2: =IF(B2="Yes", 150, 60) -> 150 | F2: =IF(C2>30,E2*0.15,IF(D2>5,IF(B2="YES",36,18),E2)) -> 150 | G2: =E2-F2 -> 0 | H2: =G2 * 7.2 -> 0 | I2: =IF(B2="Yes", 100, 40) -> 100 | J2: =IF(C2>30,I2*0.15,IF(D2>5,IF(B2="YES",24,12),I2)) -> 100 | K2: =I2-J2 -> 0 | L2: =K2 * 4 -> 0 | M2: Ideal BBQ Day | N2: 2023 | O2: May
A3: 45048 | B3: =IF( WEEKDAY(A3, 2) > 5, "YES", "NO") -> NO | C3: =_xlfn.XLOOKUP(A3,Weather_clean_data!A:A,Weather_clean_data!B:B,0) -> 17 | D3: =_xlfn.XLOOKUP(A3, Weather_clean_data!A:A, Weather_clean_data!C:C, 0) -> 0.1 | E3: =IF(B3="Yes", 150, 60) -> 60 | F3: =IF(C3>30,E3*0.15,IF(D3>5,IF(B3="YES",36,18),E3)) -> 60 | G3: =E3-F3 -> 0 | H3: =G3 * 7.2 -> 0 | I3: =IF(B3="Yes", 100, 40) -> 40 | J3: =IF(C3>30,I3*0.15,IF(D3>5,IF(B3="YES",24,12),I3)) -> 40 | K3: =I3-J3 -> 0 | L3: =K3 * 4 -> 0 | M3: Normal Weekday | N3: 2023 | O3: May
A4: 45049 | B4: =IF( WEEKDAY(A4, 2) > 5, "YES", "NO") -> NO | C4: =_xlfn.XLOOKUP(A4,Weather_clean_data!A:A,Weather_clean_data!B:B,0) -> 16 | D4: =_xlfn.XLOOKUP(A4, Weather_clean_data!A:A, Weather_clean_data!C:C, 0) -> 0 | E4: =IF(B4="Yes", 150, 60) -> 60 | F4: =IF(C4>30,E4*0.15,IF(D4>5,IF(B4="YES",36,18),E4)) -> 60 | G4: =E4-F4 -> 0 | H4: =G4 * 7.2 -> 0 | I4: =IF(B4="Yes", 100, 40) -> 40 | J4: =IF(C4>30,I4*0.15,IF(D4>5,IF(B4="YES",24,12),I4)) -> 40 | K4: =I4-J4 -> 0 | L4: =K4 * 4 -> 0 | M4: Normal Weekday | N4: 2023 | O4: May
A5: 45050 | B5: =IF( WEEKDAY(A5, 2) > 5, "YES", "NO") -> NO | C5: =_xlfn.XLOOKUP(A5,Weather_clean_data!A:A,Weather_clean_data!B:B,0) -> 18 | D5: =_xlfn.XLOOKUP(A5, Weather_clean_data!A:A, Weather_clean_data!C:C, 0) -> 1.9 | E5: =IF(B5="Yes", 150, 60) -> 60 | F5: =IF(C5>30,E5*0.15,IF(D5>5,IF(B5="YES",36,18),E5)) -> 60 | G5: =E5-F5 -> 0 | H5: =G5 * 7.2 -> 0 | I5: =IF(B5="Yes", 100, 40) -> 40 | J5: =IF(C5>30,I5*0.15,IF(D5>5,IF(B5="YES",24,12),I5)) -> 40 | K5: =I5-J5 -> 0 | L5: =K5 * 4 -> 0 | M5: Normal Weekday | N5: 2023 | O5: May
A6: 45051 | B6: =IF( WEEKDAY(A6, 2) > 5, "YES", "NO") -> NO | C6: =_xlfn.XLOOKUP(A6,Weather_clean_data!A:A,Weather_clean_data!B:B,0) -> 18 | D6: =_xlfn.XLOOKUP(A6, Weather_clean_data!A:A, Weather_clean_data!C:C, 0) -> 2.5 | E6: =IF(B6="Yes", 150, 60) -> 60 | F6: =IF(C6>30,E6*0.15,IF(D6>5,IF(B6="YES",36,18),E6)) -> 60 | G6: =E6-F6 -> 0 | H6: =G6 * 7.2 -> 0 | I6: =IF(B6="Yes", 100, 40) -> 40 | J6: =IF(C6>30,I6*0.15,IF(D6>5,IF(B6="YES",24,12),I6)) -> 40 | K6: =I6-J6 -> 0 | L6: =K6 * 4 -> 0 | M6: Ideal BBQ Day | N6: 2023 | O6: May
A7: 45052 | B7: =IF( WEEKDAY(A7, 2) > 5, "YES", "NO") -> YES | C7: =_xlfn.XLOOKUP(A7,Weather_clean_data!A:A,Weather_clean_data!B:B,0) -> 16 | D7: =_xlfn.XLOOKUP(A7, Weather_clean_data!A:A, Weather_clean_data!C:C, 0) -> 2.3 | E7: =IF(B7="Yes", 150, 60) -> 150 | F7: =IF(C7>30,E7*0.15,IF(D7>5,IF(B7="YES",36,18),E7)) -> 150 | G7: =E7-F7 -> 0 | H7: =G7 * 7.2 -> 0 | I7: =IF(B7="Yes", 100, 40) -> 100 | J7: =IF(C7>30,I7*0.15,IF(D7>5,IF(B7="YES",24,12),I7)) -> 100 | K7: =I7-J7 -> 0 | L7: =K7 * 4 -> 0 | M7: Ideal BBQ Day | N7: 2023 | O7: May
A8: 45053 | B8: =IF( WEEKDAY(A8, 2) > 5, "YES", "NO") -> YES | C8: =_xlfn.XLOOKUP(A8,Weather_clean_data!A:A,Weather_clean_data!B:B,0) -> 19 | D8: =_xlfn.XLOOKUP(A8, Weather_clean_data!A:A, Weather_clean_data!C:C, 0) -> 0 | E8: =IF(B8="Yes", 150, 60) -> 150 | F8: =IF(C8>30,E8*0.15,IF(D8>5,IF(B8="YES",36,18),E8)) -> 150 | G8: =E8-F8 -> 0 | H8: =G8 * 7.2 -> 0 | I8: =IF(B8="Yes", 100, 40) -> 100 | J8: =IF(C8>30,I8*0.15,IF(D8>5,IF(B8="YES",24,12),I8)) -> 100 | K8: =I8-J8 -> 0 | L8: =K8 * 4 -> 0 | M8: Ideal BBQ Day | N8: 2023 | O8: May
A9: 45054 | B9: YES | C9: =_xlfn.XLOOKUP(A9,Weather_clean_data!A:A,Weather_clean_data!B:B,0) -> 16 | D9: =_xlfn.XLOOKUP(A9, Weather_clean_data!A:A, Weather_clean_data!C:C, 0) -> 9.3 | E9: =IF(B9="Yes", 150, 60) -> 150 | F9: =IF(C9>30,E9*0.15,IF(D9>5,IF(B9="YES",36,18),E9)) -> 36 | G9: =E9-F9 -> 114 | H9: =G9 * 7.2 -> 820.8 | I9: =IF(B9="Yes", 100, 40) -> 100 | J9: =IF(C9>30,I9*0.15,IF(D9>5,IF(B9="YES",24,12),I9)) -> 24 | K9: =I9-J9 -> 76 | L9: =K9 * 4 -> 304 | M9: Heavy Rain | N9: 2023 | O9: May
A10: 45055 | B10: =IF( WEEKDAY(A10, 2) > 5, "YES", "NO") -> NO | C10: =_xlfn.XLOOKUP(A10,Weather_clean_data!A:A,Weather_clean_data!B:B,0) -> 18 | D10: =_xlfn.XLOOKUP(A10, Weather_clean_data!A:A, Weather_clean_data!C:C, 0) -> 10.2 | E10: =IF(B10="Yes", 150, 60) -> 60 | F10: =IF(C10>30,E10*0.15,IF(D10>5,IF(B10="YES",36,18),E10)) -> 18 | G10: =E10-F10 -> 42 | H10: =G10 * 7.2 -> 302.4 | I10: =IF(B10="Yes", 100, 40) -> 40 | J10: =IF(C10>30,I10*0.15,IF(D10>5,IF(B10="YES",24,12),I10)) -> 12 | K10: =I10-J10 -> 28 | L10: =K10 * 4 -> 112 | M10: Heavy Rain | N10: 2023 | O10: May
A11: 45056 | B11: =IF( WEEKDAY(A11, 2) > 5, "YES", "NO") -> NO | C11: =_xlfn.XLOOKUP(A11,Weather_clean_data!A:A,Weather_clean_data!B:B,0) -> 16 | D11: =_xlfn.XLOOKUP(A11, Weather_clean_data!A:A, Weather_clean_data!C:C, 0) -> 3.2 | E11: =IF(B11="Yes", 150, 60) -> 60 | F11: =IF(C11>30,E11*0.15,IF(D11>5,IF(B11="YES",36,18),E11)) -> 60 | G11: =E11-F11 -> 0 | H11: =G11 * 7.2 -> 0 | I11: =IF(B11="Yes", 100, 40) -> 40 | J11: =IF(C11>30,I11*0.15,IF(D11>5,IF(B11="YES",24,12),I11)) -> 40 | K11: =I11-J11 -> 0 | L11: =K11 * 4 -> 0 | M11: Normal Weekday | N11: 2023 | O11: May
A12: 45057 | B12: =IF( WEEKDAY(A12, 2) > 5, "YES", "NO") -> NO | C12: =_xlfn.XLOOKUP(A12,Weather_clean_data!A:A,Weather_clean_data!B:B,0) -> 19 | D12: =_xlfn.XLOOKUP(A12, Weather_clean_data!A:A, Weather_clean_data!C:C, 0) -> 0.4 | E12: =IF(B12="Yes", 150, 60) -> 60 | F12: =IF(C12>30,E12*0.15,IF(D12>5,IF(B12="YES",36,18),E12)) -> 60 | G12: =E12-F12 -> 0 | H12: =G12 * 7.2 -> 0 | I12: =IF(B12="Yes", 100, 40) -> 40 | J12: =IF(C12>30,I12*0.15,IF(D12>5,IF(B12="YES",24,12),I12)) -> 40 | K12: =I12-J12 -> 0 | L12: =K12 * 4 -> 0 | M12: Normal Weekday | N12: 2023 | O12: May
A13: 45058 | B13: =IF( WEEKDAY(A13, 2) > 5, "YES", "NO") -> NO | C13: =_xlfn.XLOOKUP(A13,Weather_clean_data!A:A,Weather_clean_data!B:B,0) -> 15 | D13: =_xlfn.XLOOKUP(A13, Weather_clean_data!A:A, Weather_clean_data!C:C, 0) -> 0.1 | E13: =IF(B13="Yes", 150, 60) -> 60 | F13: =IF(C13>30,E13*0.15,IF(D13>5,IF(B13="YES",36,18),E13)) -> 60 | G13: =E13-F13 -> 0 | H13: =G13 * 7.2 -> 0 | I13: =IF(B13="Yes", 100, 40) -> 40 | J13: =IF(C13>30,I13*0.15,IF(D13>5,IF(B13="YES",24,12),I13)) -> 40 | K13: =I13-J13 -> 0 | L13: =K13 * 4 -> 0 | M13: Ideal BBQ Day | N13: 2023 | O13: May
A14: 45059 | B14: =IF( WEEKDAY(A14, 2) > 5, "YES", "NO") -> YES | C14: =_xlfn.XLOOKUP(A14,Weather_clean_data!A:A,Weather_clean_data!B:B,0) -> 16 | D14: =_xlfn.XLOOKUP(A14, Weather_clean_data!A:A, Weather_clean_data!C:C, 0) -> 0 | E14: =IF(B14="Yes", 150, 60) -> 150 | F14: =IF(C14>30,E14*0.15,IF(D14>5,IF(B14="YES",36,18),E14)) -> 150 | G14: =E14-F14 -> 0 | H14: =G14 * 7.2 -> 0 | I14: =IF(B14="Yes", 100, 40) -> 100 | J14: =IF(C14>30,I14*0.15,IF(D14>5,IF(B14="YES",24,12),I14)) -> 100 | K14: =I14-J14 -> 0 | L14: =K14 * 4 -> 0 | M14: Ideal BBQ Day | N14: 2023 | O14: May
A15: 45060 | B15: =IF( WEEKDAY(A15, 2) > 5, "YES", "NO") -> YES | C15: =_xlfn.XLOOKUP(A15,Weather_clean_data!A:A,Weather_clean_data!B:B,0) -> 18.6 | D15: =_xlfn.XLOOKUP(A15, Weather_clean_data!A:A, Weather_clean_data!C:C, 0) -> 0.7 | E15: =IF(B15="Yes", 150, 60) -> 150 | F15: =IF(C15>30,E15*0.15,IF(D15>5,IF(B15="YES",36,18),E15)) -> 150 | G15: =E15-F15 -> 0 | H15: =G15 * 7.2 -> 0 | I15: =IF(B15="Yes", 100, 40) -> 100 | J15: =IF(C15>30,I15*0.15,IF(D15>5,IF(B15="YES",24,12),I15)) -> 100 | K15: =I15-J15 -> 0 | L15: =K15 * 4 -> 0 | M15: Ideal BBQ Day | N15: 2023 | O15: May
A16: 45061 | B16: =IF( WEEKDAY(A16, 2) > 5, "YES", "NO") -> NO | C16: =_xlfn.XLOOKUP(A16,Weather_clean_data!A:A,Weather_clean_data!B:B,0) -> 16 | D16: =_xlfn.XLOOKUP(A16, Weather_clean_data!A:A, Weather_clean_data!C:C, 0) -> 0 | E16: =IF(B16="Yes", 150, 60) -> 60 | F16: =IF(C16>30,E16*0.15,IF(D16>5,IF(B16="YES",36,18),E16)) -> 60 | G16: =E16-F16 -> 0 | H16: =G16 * 7.2 -> 0 | I16: =IF(B16="Yes", 100, 40) -> 40 | J16: =IF(C16>30,I16*0.15,IF(D16>5,IF(B16="YES",24,12),I16)) -> 40 | K16: =I16-J16 -> 0 | L16: =K16 * 4 -> 0 | M16: Normal Weekday | N16: 2023 | O16: May
A17: 45062 | B17: =IF( WEEKDAY(A17, 2) > 5, "YES", "NO") -> NO | C17: =_xlfn.XLOOKUP(A17,Weather_clean_data!A:A,Weather_clean_data!B:B,0) -> 17 | D17: =_xlfn.XLOOKUP(A17, Weather_clean_data!A:A, Weather_clean_data!C:C, 0) -> 0 | E17: =IF(B17="Yes", 150, 60) -> 60 | F17: =IF(C17>30,E17*0.15,IF(D17>5,IF(B17="YES",36,18),E17)) -> 60 | G17: =E17-F17 -> 0 | H17: =G17 * 7.2 -> 0 | I17: =IF(B17="Yes", 100, 40) -> 40 | J17: =IF(C17>30,I17*0.15,IF(D17>5,IF(B17="YES",24,12),I17)) -> 40 | K17: =I17-J17 -> 0 | L17: =K17 * 4 -> 0 | M17: Normal Weekday | N17: 2023 | O17: May
A18: 45063 | B18: =IF( WEEKDAY(A18, 2) > 5, "YES", "NO") -> NO | C18: =_xlfn.XLOOKUP(A18,Weather_clean_data!A:A,Weather_clean_data!B:B,0) -> 18 | D18: =_xlfn.XLOOKUP(A18, Weather_clean_data!A:A, Weather_clean_data!C:C, 0) -> 0 | E18: =IF(B18="Yes", 150, 60) -> 60 | F18: =IF(C18>30,E18*0.15,IF(D18>5,IF(B18="YES",36,18),E18)) -> 60 | G18: =E18-F18 -> 0 | H18: =G18 * 7.2 -> 0 | I18: =IF(B18="Yes", 100, 40) -> 40 | J18: =IF(C18>30,I18*0.15,IF(D18>5,IF(B18="YES",24,12),I18)) -> 40 | K18: =I18-J18 -> 0 | L18: =K18 * 4 -> 0 | M18: Normal Weekday | N18: 2023 | O18: May
A19: 45064 | B19: =IF( WEEKDAY(A19, 2) > 5, "YES", "NO") -> NO | C19: =_xlfn.XLOOKUP(A19,Weather_clean_data!A:A,Weather_clean_data!B:B,0) -> 21 | D19: =_xlfn.XLOOKUP(A19, Weather_clean_data!A:A, Weather_clean_data!C:C, 0) -> 0 | E19: =IF(B19="Yes", 150, 60) -> 60 | F19: =IF(C19>30,E19*0.15,IF(D19>5,IF(B19="YES",36,18),E19)) -> 60 | G19: =E19-F19 -> 0 | H19: =G19 * 7.2 -> 0 | I19: =IF(B19="Yes", 100, 40) -> 40 | J19: =IF(C19>30,I19*0.15,IF(D19>5,IF(B19="YES",24,12),I19)) -> 40 | K19: =I19-J19 -> 0 | L19: =K19 * 4 -> 0 | M19: Normal Weekday | N19: 2023 | O19: May
A20: 45065 | B20: =IF( WEEKDAY(A20, 2) > 5, "YES", "NO") -> NO | C20: =_xlfn.XLOOKUP(A20,Weather_clean_data!A:A,Weather_clean_data!B:B,0) -> 19 | D20: =_xlfn.XLOOKUP(A20, Weather_clean_data!A:A, Weather_clean_data!C:C, 0) -> 2.3 | E20: =IF(B20="Yes", 150, 60) -> 60 | F20: =IF(C20>30,E20*0.15,IF(D20>5,IF(B20="YES",36,18),E20)) -> 60 | G20: =E20-F20 -> 0 | H20: =G20 * 7.2 -> 0 | I20: =IF(B20="Yes", 100, 40) -> 40 | J20: =IF(C20>30,I20*0.15,IF(D20>5,IF(B20="YES",24,12),I20)) -> 40 | K20: =I20-J20 -> 0 | L20: =K20 * 4 -> 0 | M20: Ideal BBQ Day | N20: 2023 | O20: May
A21: 45066 | B21: =IF( WEEKDAY(A21, 2) > 5, "YES", "NO") -> YES | C21: =_xlfn.XLOOKUP(A21,Weather_clean_data!A:A,Weather_clean_data!B:B,0) -> 19 | D21: =_xlfn.XLOOKUP(A21, Weather_clean_data!A:A, Weather_clean_data!C:C, 0) -> 0 | E21: =IF(B21="Yes", 150, 60) -> 150 | F21: =IF(C21>30,E21*0.15,IF(D21>5,IF(B21="YES",36,18),E21)) -> 150 | G21: =E21-F21 -> 0 | H21: =G21 * 7.2 -> 0 | I21: =IF(B21="Yes", 100, 40) -> 100 | J21: =IF(C21>30,I21*0.15,IF(D21>5,IF(B21="YES",24,12),I21)) -> 100 | K21: =I21-J21 -> 0 | L21: =K21 * 4 -> 0 | M21: Ideal BBQ Day | N21: 2023 | O21: May
... A29: 45074 | B29: =IF( WEEKDAY(A29, 2) > 5, "YES", "NO") -> YES | C29: =_xlfn.XLOOKUP(A29,Weather_clean_data!A:A,Weather_clean_data!B:B,0) -> 22 | D29: =_xlfn.XLOOKUP(A29, Weather_clean_data!A:A, Weather_clean_data!C:C, 0) -> 0 | E29: =IF(B29="Yes", 150, 60) -> 150 | F29: =IF(C29>30,E29*0.15,IF(D29>5,IF(B29="YES",36,18),E29)) -> 150 | G29: =E29-F29 -> 0 | H29: =G29 * 7.2 -> 0 | I29: =IF(B29="Yes", 100, 40) -> 100 | J29: =IF(C29>30,I29*0.15,IF(D29>5,IF(B29="YES",24,12),I29)) -> 100 | K29: =I29-J29 -> 0 | L29: =K29 * 4 -> 0 | M29: Ideal BBQ Day | N29: 2023 | O29: May
A30: 45075 | B30: YES | C30: =_xlfn.XLOOKUP(A30,Weather_clean_data!A:A,Weather_clean_data!B:B,0) -> 18 | D30: =_xlfn.XLOOKUP(A30, Weather_clean_data!A:A, Weather_clean_data!C:C, 0) -> 0 | E30: =IF(B30="Yes", 150, 60) -> 150 | F30: =IF(C30>30,E30*0.15,IF(D30>5,IF(B30="YES",36,18),E30)) -> 150 | G30: =E30-F30 -> 0 | H30: =G30 * 7.2 -> 0 | I30: =IF(B30="Yes", 100, 40) -> 100 | J30: =IF(C30>30,I30*0.15,IF(D30>5,IF(B30="YES",24,12),I30)) -> 100 | K30: =I30-J30 -> 0 | L30: =K30 * 4 -> 0 | M30: Ideal BBQ Day | N30: 2023 | O30: May
A31: 45076 | B31: =IF( WEEKDAY(A31, 2) > 5, "YES", "NO") -> NO | C31: =_xlfn.XLOOKUP(A31,Weather_clean_data!A:A,Weather_clean_data!B:B,0) -> 18 | D31: =_xlfn.XLOOKUP(A31, Weather_clean_data!A:A, Weather_clean_data!C:C, 0) -> 0 | E31: =IF(B31="Yes", 150, 60) -> 60 | F31: =IF(C31>30,E31*0.15,IF(D31>5,IF(B31="YES",36,18),E31)) -> 60 | G31: =E31-F31 -> 0 | H31: =G31 * 7.2 -> 0 | I31: =IF(B31="Yes", 100, 40) -> 40 | J31: =IF(C31>30,I31*0.15,IF(D31>5,IF(B31="YES",24,12),I31)) -> 40 | K31: =I31-J31 -> 0 | L31: =K31 * 4 -> 0 | M31: Normal Weekday | N31: 2023 | O31: May
A32: 45077 | B32: =IF( WEEKDAY(A32, 2) > 5, "YES", "NO") -> NO | C32: =_xlfn.XLOOKUP(A32,Weather_clean_data!A:A,Weather_clean_data!B:B,0) -> 15.2 | D32: =_xlfn.XLOOKUP(A32, Weather_clean_data!A:A, Weather_clean_data!C:C, 0) -> 0 | E32: =IF(B32="Yes", 150, 60) -> 60 | F32: =IF(C32>30,E32*0.15,IF(D32>5,IF(B32="YES",36,18),E32)) -> 60 | G32: =E32-F32 -> 0 | H32: =G32 * 7.2 -> 0 | I32: =IF(B32="Yes", 100, 40) -> 40 | J32: =IF(C32>30,I32*0.15,IF(D32>5,IF(B32="YES",24,12),I32)) -> 40 | K32: =I32-J32 -> 0 | L32: =K32 * 4 -> 0 | M32: Normal Weekday | N32: 2023 | O32: May
A33: 45078 | B33: =IF( WEEKDAY(A33, 2) > 5, "YES", "NO") -> NO | C33: =_xlfn.XLOOKUP(A33,Weather_clean_data!A:A,Weather_clean_data!B:B,0) -> 18 | D33: =_xlfn.XLOOKUP(A33, Weather_clean_data!A:A, Weather_clean_data!C:C, 0) -> 0 | E33: =IF(B33="Yes", 150, 60) -> 60 | F33: =IF(C33>30,E33*0.15,IF(D33>5,IF(B33="YES",36,18),E33)) -> 60 | G33: =E33-F33 -> 0 | H33: =G33 * 7.2 -> 0 | I33: =IF(B33="Yes", 100, 40) -> 40 | J33: =IF(C33>30,I33*0.15,IF(D33>5,IF(B33="YES",24,12),I33)) -> 40 | K33: =I33-J33 -> 0 | L33: =K33 * 4 -> 0 | M33: Normal Weekday | N33: 2023 | O33: June
A34: 45079 | B34: =IF( WEEKDAY(A34, 2) > 5, "YES", "NO") -> NO | C34: =_xlfn.XLOOKUP(A34,Weather_clean_data!A:A,Weather_clean_data!B:B,0) -> 19 | D34: =_xlfn.XLOOKUP(A34, Weather_clean_data!A:A, Weather_clean_data!C:C, 0) -> 0 | E34: =IF(B34="Yes", 150, 60) -> 60 | F34: =IF(C34>30,E34*0.15,IF(D34>5,IF(B34="YES",36,18),E34)) -> 60 | G34: =E34-F34 -> 0 | H34: =G34 * 7.2 -> 0 | I34: =IF(B34="Yes", 100, 40) -> 40 | J34: =IF(C34>30,I34*0.15,IF(D34>5,IF(B34="YES",24,12),I34)) -> 40 | K34: =I34-J34 -> 0 | L34: =K34 * 4 -> 0 | M34: Ideal BBQ Day | N34: 2023 | O34: June
A35: 45080 | B35: =IF( WEEKDAY(A35, 2) > 5, "YES", "NO") -> YES | C35: =_xlfn.XLOOKUP(A35,Weather_clean_data!A:A,Weather_clean_data!B:B,0) -> 22 | D35: =_xlfn.XLOOKUP(A35, Weather_clean_data!A:A, Weather_clean_data!C:C, 0) -> 0 | E35: =IF(B35="Yes", 150, 60) -> 150 | F35: =IF(C35>30,E35*0.15,IF(D35>5,IF(B35="YES",36,18),E35)) -> 150 | G35: =E35-F35 -> 0 | H35: =G35 * 7.2 -> 0 | I35: =IF(B35="Yes", 100, 40) -> 100 | J35: =IF(C35>30,I35*0.15,IF(D35>5,IF(B35="YES",24,12),I35)) -> 100 | K35: =I35-J35 -> 0 | L35: =K35 * 4 -> 0 | M35: Ideal BBQ Day | N35: 2023 | O35: June
A36: 45081 | B36: =IF( WEEKDAY(A36, 2) > 5, "YES", "NO") -> YES | C36: =_xlfn.XLOOKUP(A36,Weather_clean_data!A:A,Weather_clean_data!B:B,0) -> 21 | D36: =_xlfn.XLOOKUP(A36, Weather_clean_data!A:A, Weather_clean_data!C:C, 0) -> 0 | E36: =IF(B36="Yes", 150, 60) -> 150 | F36: =IF(C36>30,E36*0.15,IF(D36>5,IF(B36="YES",36,18),E36)) -> 150 | G36: =E36-F36 -> 0 | H36: =G36 * 7.2 -> 0 | I36: =IF(B36="Yes", 100, 40) -> 100 | J36: =IF(C36>30,I36*0.15,IF(D36>5,IF(B36="YES",24,12),I36)) -> 100 | K36: =I36-J36 -> 0 | L36: =K36 * 4 -> 0 | M36: Ideal BBQ Day | N36: 2023 | O36: June
A37: 45082 | B37: =IF( WEEKDAY(A37, 2) > 5, "YES", "NO") -> NO | C37: =_xlfn.XLOOKUP(A37,Weather_clean_data!A:A,Weather_clean_data!B:B,0) -> 18 | D37: =_xlfn.XLOOKUP(A37, Weather_clean_data!A:A, Weather_clean_data!C:C, 0) -> 0 | E37: =IF(B37="Yes", 150, 60) -> 60 | F37: =IF(C37>30,E37*0.15,IF(D37>5,IF(B37="YES",36,18),E37)) -> 60 | G37: =E37-F37 -> 0 | H37: =G37 * 7.2 -> 0 | I37: =IF(B37="Yes", 100, 40) -> 40 | J37: =IF(C37>30,I37*0.15,IF(D37>5,IF(B37="YES",24,12),I37)) -> 40 | K37: =I37-J37 -> 0 | L37: =K37 * 4 -> 0 | M37: Normal Weekday | N37: 2023 | O37: June
A38: 45083 | B38: =IF( WEEKDAY(A38, 2) > 5, "YES", "NO") -> NO | C38: =_xlfn.XLOOKUP(A38,Weather_clean_data!A:A,Weather_clean_data!B:B,0) -> 16 | D38: =_xlfn.XLOOKUP(A38, Weather_clean_data!A:A, Weather_clean_data!C:C, 0) -> 0 | E38: =IF(B38="Yes", 150, 60) -> 60 | F38: =IF(C38>30,E38*0.15,IF(D38>5,IF(B38="YES",36,18),E38)) -> 60 | G38: =E38-F38 -> 0 | H38: =G38 * 7.2 -> 0 | I38: =IF(B38="Yes", 100, 40) -> 40 | J38: =IF(C38>30,I38*0.15,IF(D38>5,IF(B38="YES",24,12),I38)) -> 40 | K38: =I38-J38 -> 0 | L38: =K38 * 4 -> 0 | M38: Normal Weekday | N38: 2023 | O38: June
A39: 45084 | B39: =IF( WEEKDAY(A39, 2) > 5, "YES", "NO") -> NO | C39: =_xlfn.XLOOKUP(A39,Weather_clean_data!A:A,Weather_clean_data!B:B,0) -> 21 | D39: =_xlfn.XLOOKUP(A39, Weather_clean_data!A:A, Weather_clean_data!C:C, 0) -> 0 | E39: =IF(B39="Yes", 150, 60) -> 60 | F39: =IF(C39>30,E39*0.15,IF(D39>5,IF(B39="YES",36,18),E39)) -> 60 | G39: =E39-F39 -> 0 | H39: =G39 * 7.2 -> 0 | I39: =IF(B39="Yes", 100, 40) -> 40 | J39: =IF(C39>30,I39*0.15,IF(D39>5,IF(B39="YES",24,12),I39)) -> 40 | K39: =I39-J39 -> 0 | L39: =K39 * 4 -> 0 | M39: Normal Weekday | N39: 2023 | O39: June
A40: 45085 | B40: =IF( WEEKDAY(A40, 2) > 5, "YES", "NO") -> NO | C40: =_xlfn.XLOOKUP(A40,Weather_clean_data!A:A,Weather_clean_data!B:B,0) -> 22 | D40: =_xlfn.XLOOKUP(A40, Weather_clean_data!A:A, Weather_clean_data!C:C, 0) -> 0 | E40: =IF(B40="Yes", 150, 60) -> 60 | F40: =IF(C40>30,E40*0.15,IF(D40>5,IF(B40="YES",36,18),E40)) -> 60 | G40: =E40-F40 -> 0 | H40: =G40 * 7.2 -> 0 | I40: =IF(B40="Yes", 100, 40) -> 40 | J40: =IF(C40>30,I40*0.15,IF(D40>5,IF(B40="YES",24,12),I40)) -> 40 | K40: =I40-J40 -> 0 | L40: =K40 * 4 -> 0 | M40: Normal Weekday | N40: 2023 | O40: June
A41: 45086 | B41: =IF( WEEKDAY(A41, 2) > 5, "YES", "NO") -> NO | C41: =_xlfn.XLOOKUP(A41,Weather_clean_data!A:A,Weather_clean_data!B:B,0) -> 25 | D41: =_xlfn.XLOOKUP(A41, Weather_clean_data!A:A, Weather_clean_data!C:C, 0) -> 0 | E41: =IF(B41="Yes", 150, 60) -> 60 | F41: =IF(C41>30,E41*0.15,IF(D41>5,IF(B41="YES",36,18),E41)) -> 60 | G41: =E41-F41 -> 0 | H41: =G41 * 7.2 -> 0 | I41: =IF(B41="Yes", 100, 40) -> 40 | J41: =IF(C41>30,I41*0.15,IF(D41>5,IF(B41="YES",24,12),I41)) -> 40 | K41: =I41-J41 -> 0 | L41: =K41 * 4 -> 0 | M41: Ideal BBQ Day | N41: 2023 | O41: June
A42: 45087 | B42: =IF( WEEKDAY(A42, 2) > 5, "YES", "NO") -> YES | C42: =_xlfn.XLOOKUP(A42,Weather_clean_data!A:A,Weather_clean_data!B:B,0) -> 29 | D42: =_xlfn.XLOOKUP(A42, Weather_clean_data!A:A, Weather_clean_data!C:C, 0) -> 0.8 | E42: =IF(B42="Yes", 150, 60) -> 150 | F42: =IF(C42>30,E42*0.15,IF(D42>5,IF(B42="YES",36,18),E42)) -> 150 | G42: =E42-F42 -> 0 | H42: =G42 * 7.2 -> 0 | I42: =IF(B42="Yes", 100, 40) -> 100 | J42: =IF(C42>30,I42*0.15,IF(D42>5,IF(B42="YES",24,12),I42)) -> 100 | K42: =I42-J42 -> 0 | L42: =K42 * 4 -> 0 | M42: Ideal BBQ Day | N42: 2023 | O42: June
... A127: 45781 | B127: =IF( WEEKDAY(A127, 2) > 5, "YES", "NO") -> YES | C127: =_xlfn.XLOOKUP(A127,Weather_clean_data!A:A,Weather_clean_data!B:B,0) -> 14 | D127: =_xlfn.XLOOKUP(A127, Weather_clean_data!A:A, Weather_clean_data!C:C, 0) -> 0 | E127: =IF(B127="Yes", 150, 60) -> 150 | F127: =IF(C127>30,E127*0.15,IF(D127>5,IF(B127="YES",36,18),E127)) -> 150 | G127: =E127-F127 -> 0 | H127: =G127 * 7.2 -> 0 | I127: =IF(B127="Yes", 100, 40) -> 100 | J127: =IF(C127>30,I127*0.15,IF(D127>5,IF(B127="YES",24,12),I127)) -> 100 | K127: =I127-J127 -> 0 | L127: =K127 * 4 -> 0 | M127: Ideal BBQ Day | N127: 2025 | O127: May
A128: 45782 | B128: YES | C128: =_xlfn.XLOOKUP(A128,Weather_clean_data!A:A,Weather_clean_data!B:B,0) -> 14 | D128: =_xlfn.XLOOKUP(A128, Weather_clean_data!A:A, Weather_clean_data!C:C, 0) -> 0 | E128: =IF(B128="Yes", 150, 60) -> 150 | F128: =IF(C128>30,E128*0.15,IF(D128>5,IF(B128="YES",36,18),E128)) -> 150 | G128: =E128-F128 -> 0 | H128: =G128 * 7.2 -> 0 | I128: =IF(B128="Yes", 100, 40) -> 100 | J128: =IF(C128>30,I128*0.15,IF(D128>5,IF(B128="YES",24,12),I128)) -> 100 | K128: =I128-J128 -> 0 | L128: =K128 * 4 -> 0 | M128: Ideal BBQ Day | N128: 2025 | O128: May
A129: 45783 | B129: =IF( WEEKDAY(A129, 2) > 5, "YES", "NO") -> NO | C129: =_xlfn.XLOOKUP(A129,Weather_clean_data!A:A,Weather_clean_data!B:B,0) -> 15 | D129: =_xlfn.XLOOKUP(A129, Weather_clean_data!A:A, Weather_clean_data!C:C, 0) -> 0 | E129: =IF(B129="Yes", 150, 60) -> 60 | F129: =IF(C129>30,E129*0.15,IF(D129>5,IF(B129="YES",36,18),E129)) -> 60 | G129: =E129-F129 -> 0 | H129: =G129 * 7.2 -> 0 | I129: =IF(B129="Yes", 100, 40) -> 40 | J129: =IF(C129>30,I129*0.15,IF(D129>5,IF(B129="YES",24,12),I129)) -> 40 | K129: =I129-J129 -> 0 | L129: =K129 * 4 -> 0 | M129: Normal Weekday | N129: 2025 | O129: May
A130: 45784 | B130: =IF( WEEKDAY(A130, 2) > 5, "YES", "NO") -> NO | C130: =_xlfn.XLOOKUP(A130,Weather_clean_data!A:A,Weather_clean_data!B:B,0) -> 18 | D130: =_xlfn.XLOOKUP(A130, Weather_clean_data!A:A, Weather_clean_data!C:C, 0) -> 0 | E130: =IF(B130="Yes", 150, 60) -> 60 | F130: =IF(C130>30,E130*0.15,IF(D130>5,IF(B130="YES",36,18),E130)) -> 60 | G130: =E130-F130 -> 0 | H130: =G130 * 7.2 -> 0 | I130: =IF(B130="Yes", 100, 40) -> 40 | J130: =IF(C130>30,I130*0.15,IF(D130>5,IF(B130="YES",24,12),I130)) -> 40 | K130: =I130-J130 -> 0 | L130: =K130 * 4 -> 0 | M130: Normal Weekday | N130: 2025 | O130: May
A131: 45785 | B131: =IF( WEEKDAY(A131, 2) > 5, "YES", "NO") -> NO | C131: =_xlfn.XLOOKUP(A131,Weather_clean_data!A:A,Weather_clean_data!B:B,0) -> 14 | D131: =_xlfn.XLOOKUP(A131, Weather_clean_data!A:A, Weather_clean_data!C:C, 0) -> 0 | E131: =IF(B131="Yes", 150, 60) -> 60 | F131: =IF(C131>30,E131*0.15,IF(D131>5,IF(B131="YES",36,18),E131)) -> 60 | G131: =E131-F131 -> 0 | H131: =G131 * 7.2 -> 0 | I131: =IF(B131="Yes", 100, 40) -> 40 | J131: =IF(C131>30,I131*0.15,IF(D131>5,IF(B131="YES",24,12),I131)) -> 40 | K131: =I131-J131 -> 0 | L131: =K131 * 4 -> 0 | M131: Normal Weekday | N131: 2025 | O131: May
...

Sheet Weather_clean_data
A1: Date | B1: tmax | C1: prcp
A2: 45047 | B2: 18 | C2: 1.3
A3: 45048 | B3: 17 | C3: 0.1
A4: 45049 | B4: 16 | C4: 0
A5: 45050 | B5: 18 | C5: 1.9
A6: 45051 | B6: 18 | C6: 2.5
A7: 45052 | B7: 16 | C7: 2.3
A8: 45053 | B8: 19 | C8: 0
A9: 45054 | B9: 16 | C9: 9.3
A10: 45055 | B10: 18 | C10: 10.2
A11: 45056 | B11: 16 | C11: 3.2
A12: 45057 | B12: 19 | C12: 0.4
A13: 45058 | B13: 15 | C13: 0.1
... A239: 46197 | B239: 35.3 | C239: 0
A240: 46198
A241: 46199
A242: 46200
A243: 46201
A244: 46202
A245: 46203

Sheet Calculations
A1: Row Labels | B1: Sum of Beef_Financial_Loss_£ | C1: Sum of Pork_Financial_Loss_£
A2: Extreme Heat | B2: 3672 | C2: 1360
A3: Heavy Rain | B3: 9374.4 | C3: 3472
A4: Ideal BBQ Day | B4: 0 | C4: 0
A5: Normal Weekday | B5: 367.2 | C5: 136
A6: Grand Total | B6: 13413.6 | C6: 4968
A10: Row Labels | B10: Average of Beef_Financial_Loss_£ | C10: Average of Pork_Financial_Loss_£
A11: Extreme Heat | B11: 524.57143 | C11: 194.28571
A12: Heavy Rain | B12: 493.38947 | C12: 182.73684
A13: Ideal BBQ Day | B13: 0 | C13: 0
A14: Normal Weekday | B14: 3.1930435 | C14: 1.1826087
A15: Grand Total | B15: 54.97377 | C15: 20.360656
A19: Sum. Beef&Pork (Extreme Heat) | B19: Sum. Beef&Pork (Heavy Rain) | C19: Sum. Beef&Pork (Standart Weekend)
A20: =GETPIVOTDATA("Average of Beef_Financial_Loss_£",Calculations!$A$10,"Weather_Condition","Extreme Heat")+GETPIVOTDATA("Average of Pork_Financial_Loss_£",Calculations!$A$10,"Weather_Condition","Extreme Heat") -> 718.85714 | B20: =GETPIVOTDATA("Average of Beef_Financial_Loss_£",Calculations!$A$10,"Weather_Condition","Heavy Rain")+GETPIVOTDATA("Average of Pork_Financial_Loss_£",Calculations!$A$10,"Weather_Condition","Heavy Rain") -> 676.12632 | C20: =IFERROR(GETPIVOTDATA("Average of Beef_Financial_Loss_£",'Performance Dashboard'!$A$60,"Weather_Condition","Normal Weekday")+GETPIVOTDATA("Average of Pork_Financial_Loss_£",'Performance Dashboard'!$A$60,"Weather_Condition","Normal Weekday"), 0) -> 0
A24: Category | B24: Demand Change (Extreme Heat) | C24: Business Action
A25: Beef & Pork | B25: -0.85 | C25: Reduce purchases, protect the margin
A26: Soft Drinks | B26: 2.4 | C26: Increase the facing on the shelves
A27: Ice Cream | B27: 3.1 | C27: Urgently check the freezers
A28: Bagged Ice | B28: 4.5 | C28: Maximum delivery priority
A33: Total Heatwave Loss | B33: 5032
A34: Prevented Loss | B34: =B33 * 0.85 -> 4277.2
A35: Remaining Loss | B35: =B33 * 0.15 -> 754.8
A38: Sourcing Strategy | B38: Financial Impact (£) | C38: Type
A39: Traditional Sourcing (Blind) | B39: =B33 -> 5032 | C39: Real Loss
A40: Smart Sourcing (With Forecast) | B40: =B35 -> 754.8 | C40: Remaining Risk
A41: Net Savings (Твоя аналітика) | B41: =B34 -> 4277.2 | C41: Money Saved

Sheet Performance Dashboard
